2021-09-09 23:45:26,548: Forbidden (CSRF token missing or incorrect.): /customerlogin
2021-09-09 23:46:10,457: C:\ecommerce\ecommerce\settings.py changed, reloading.
2021-09-09 23:46:10,458: Using proactor: IocpProactor
2021-09-09 23:48:05,524: Forbidden (CSRF token missing or incorrect.): /customerlogin
2021-09-09 23:48:20,773: C:\ecommerce\ecommerce\settings.py changed, reloading.
2021-09-09 23:48:20,773: Using proactor: IocpProactor
2021-09-09 23:49:20,419: Using proactor: IocpProactor
2021-09-09 23:54:24,226: Using proactor: IocpProactor
2021-09-09 23:57:37,602: C:\ecommerce\ecom\views.py changed, reloading.
2021-09-09 23:57:37,603: Using proactor: IocpProactor
2021-09-09 23:58:06,950: C:\ecommerce\ecom\views.py changed, reloading.
2021-09-09 23:58:06,951: Using proactor: IocpProactor
2021-09-10 00:11:54,442: C:\ecommerce\ecom\views.py changed, reloading.
2021-09-10 00:11:54,446: Using proactor: IocpProactor
2021-09-10 00:13:48,004: C:\ecommerce\ecom\views.py changed, reloading.
2021-09-10 00:13:48,005: Using proactor: IocpProactor
2021-09-10 00:14:51,279: C:\ecommerce\ecom\views.py changed, reloading.
2021-09-10 00:14:51,280: Using proactor: IocpProactor
2021-09-10 00:15:48,570: C:\ecommerce\ecom\views.py changed, reloading.
2021-09-10 00:15:48,571: Using proactor: IocpProactor
2021-09-10 00:26:31,107: C:\ecommerce\ecom\views.py changed, reloading.
2021-09-10 00:26:31,108: Using proactor: IocpProactor
2021-09-10 00:28:00,213: C:\ecommerce\ecom\views.py changed, reloading.
2021-09-10 00:28:00,214: Using proactor: IocpProactor
2021-09-10 00:28:08,976: C:\ecommerce\ecom\views.py changed, reloading.
2021-09-10 00:28:08,978: Using proactor: IocpProactor
2021-09-10 00:28:37,850: C:\ecommerce\ecom\views.py changed, reloading.
2021-09-10 00:28:37,851: Using proactor: IocpProactor
2021-09-10 00:29:01,752: C:\ecommerce\ecom\views.py changed, reloading.
2021-09-10 00:29:01,753: Using proactor: IocpProactor
2021-09-10 00:29:46,423: C:\ecommerce\ecom\views.py changed, reloading.
2021-09-10 00:29:46,426: Using proactor: IocpProactor
2021-09-10 00:31:19,731: C:\ecommerce\ecom\views.py changed, reloading.
2021-09-10 00:31:19,732: Using proactor: IocpProactor
2021-09-10 00:31:47,174: C:\ecommerce\ecom\views.py changed, reloading.
2021-09-10 00:31:47,176: Using proactor: IocpProactor
2021-09-10 00:39:39,996: Using proactor: IocpProactor
2021-09-10 01:20:56,482: C:\ecommerce\ecom\views.py changed, reloading.
2021-09-10 01:20:56,486: Using proactor: IocpProactor
2021-09-10 01:23:15,220: C:\ecommerce\ecom\views.py changed, reloading.
2021-09-10 01:23:15,222: Using proactor: IocpProactor
2021-09-10 01:24:24,987: C:\ecommerce\ecom\views.py changed, reloading.
2021-09-10 01:24:24,989: Using proactor: IocpProactor
2021-09-10 01:24:57,918: C:\ecommerce\ecom\views.py changed, reloading.
2021-09-10 01:24:57,919: Using proactor: IocpProactor
2021-09-10 01:25:04,033: Unhandled exception in listener callback
Traceback (most recent call last):
  File "C:\Users\hp\AppData\Local\Programs\Python\Python38\lib\site-packages\pynput\_util\win32.py", line 380, in _handler
    converted = self._convert(code, msg, lpdata)
  File "C:\Users\hp\AppData\Local\Programs\Python\Python38\lib\site-packages\pynput\_util\win32.py", line 395, in _convert
    raise NotImplementedError()
NotImplementedError

During handling of the above exception, another exception occurred:

Traceback (most recent call last):
  File "C:\Users\hp\AppData\Local\Programs\Python\Python38\lib\site-packages\pynput\_util\__init__.py", line 211, in inner
    return f(self, *args, **kwargs)
  File "C:\Users\hp\AppData\Local\Programs\Python\Python38\lib\site-packages\pynput\_util\win32.py", line 384, in _handler
    self._handle(code, msg, lpdata)
  File "C:\Users\hp\AppData\Local\Programs\Python\Python38\lib\site-packages\pynput\mouse\_win32.py", line 212, in _handle
    self.on_click(data.pt.x, data.pt.y, button, pressed)
  File "C:\Users\hp\AppData\Local\Programs\Python\Python38\lib\site-packages\pynput\_util\__init__.py", line 127, in inner
    if f(*args) is False:
  File "C:\ecommerce\ecom\views.py", line 103, in on_click
    if not running:  # to run only one `process`
NameError: name 'running' is not defined
2021-09-10 01:25:04,235: Internal Server Error: /afterlogin
Traceback (most recent call last):
  File "C:\Users\hp\AppData\Local\Programs\Python\Python38\lib\site-packages\pynput\_util\win32.py", line 380, in _handler
    converted = self._convert(code, msg, lpdata)
  File "C:\Users\hp\AppData\Local\Programs\Python\Python38\lib\site-packages\pynput\_util\win32.py", line 395, in _convert
    raise NotImplementedError()
NotImplementedError

During handling of the above exception, another exception occurred:

Traceback (most recent call last):
  File "C:\Users\hp\AppData\Local\Programs\Python\Python38\lib\site-packages\django\core\handlers\exception.py", line 34, in inner
    response = get_response(request)
  File "C:\Users\hp\AppData\Local\Programs\Python\Python38\lib\site-packages\django\core\handlers\base.py", line 115, in _get_response
    response = self.process_exception_by_middleware(e, request)
  File "C:\Users\hp\AppData\Local\Programs\Python\Python38\lib\site-packages\django\core\handlers\base.py", line 113, in _get_response
    response = wrapped_callback(request, *callback_args, **callback_kwargs)
  File "C:\ecommerce\ecom\views.py", line 117, in afterlogin_view
    listener.join()
  File "C:\Users\hp\AppData\Local\Programs\Python\Python38\lib\site-packages\pynput\_util\__init__.py", line 259, in join
    six.reraise(exc_type, exc_value, exc_traceback)
  File "C:\Users\hp\AppData\Local\Programs\Python\Python38\lib\site-packages\six.py", line 702, in reraise
    raise value.with_traceback(tb)
  File "C:\Users\hp\AppData\Local\Programs\Python\Python38\lib\site-packages\pynput\_util\__init__.py", line 211, in inner
    return f(self, *args, **kwargs)
  File "C:\Users\hp\AppData\Local\Programs\Python\Python38\lib\site-packages\pynput\_util\win32.py", line 384, in _handler
    self._handle(code, msg, lpdata)
  File "C:\Users\hp\AppData\Local\Programs\Python\Python38\lib\site-packages\pynput\mouse\_win32.py", line 212, in _handle
    self.on_click(data.pt.x, data.pt.y, button, pressed)
  File "C:\Users\hp\AppData\Local\Programs\Python\Python38\lib\site-packages\pynput\_util\__init__.py", line 127, in inner
    if f(*args) is False:
  File "C:\ecommerce\ecom\views.py", line 103, in on_click
    if not running:  # to run only one `process`
NameError: name 'running' is not defined
2021-09-10 01:25:51,135: C:\ecommerce\ecom\views.py changed, reloading.
2021-09-10 01:25:51,136: Using proactor: IocpProactor
2021-09-10 01:27:09,762: C:\ecommerce\ecom\views.py changed, reloading.
2021-09-10 01:27:09,825: Using proactor: IocpProactor
2021-09-10 01:27:14,099: C:\ecommerce\ecom\views.py changed, reloading.
2021-09-10 01:27:14,106: Using proactor: IocpProactor
2021-09-10 01:28:23,310: C:\ecommerce\ecom\views.py changed, reloading.
2021-09-10 01:28:23,311: Using proactor: IocpProactor
2021-09-10 01:35:42,412: C:\ecommerce\ecom\views.py changed, reloading.
2021-09-10 01:35:42,417: Using proactor: IocpProactor
2021-09-10 01:35:48,824: Unhandled exception in listener callback
Traceback (most recent call last):
  File "C:\Users\hp\AppData\Local\Programs\Python\Python38\lib\site-packages\pynput\_util\win32.py", line 380, in _handler
    converted = self._convert(code, msg, lpdata)
  File "C:\Users\hp\AppData\Local\Programs\Python\Python38\lib\site-packages\pynput\_util\win32.py", line 395, in _convert
    raise NotImplementedError()
NotImplementedError

During handling of the above exception, another exception occurred:

Traceback (most recent call last):
  File "C:\Users\hp\AppData\Local\Programs\Python\Python38\lib\site-packages\pynput\_util\__init__.py", line 211, in inner
    return f(self, *args, **kwargs)
  File "C:\Users\hp\AppData\Local\Programs\Python\Python38\lib\site-packages\pynput\_util\win32.py", line 384, in _handler
    self._handle(code, msg, lpdata)
  File "C:\Users\hp\AppData\Local\Programs\Python\Python38\lib\site-packages\pynput\mouse\_win32.py", line 212, in _handle
    self.on_click(data.pt.x, data.pt.y, button, pressed)
  File "C:\Users\hp\AppData\Local\Programs\Python\Python38\lib\site-packages\pynput\_util\__init__.py", line 127, in inner
    if f(*args) is False:
  File "C:\ecommerce\ecom\views.py", line 103, in on_click
    if not running:  # to run only one `process`
NameError: name 'running' is not defined
2021-09-10 01:35:48,914: Internal Server Error: /afterlogin
Traceback (most recent call last):
  File "C:\Users\hp\AppData\Local\Programs\Python\Python38\lib\site-packages\pynput\_util\win32.py", line 380, in _handler
    converted = self._convert(code, msg, lpdata)
  File "C:\Users\hp\AppData\Local\Programs\Python\Python38\lib\site-packages\pynput\_util\win32.py", line 395, in _convert
    raise NotImplementedError()
NotImplementedError

During handling of the above exception, another exception occurred:

Traceback (most recent call last):
  File "C:\Users\hp\AppData\Local\Programs\Python\Python38\lib\site-packages\django\core\handlers\exception.py", line 34, in inner
    response = get_response(request)
  File "C:\Users\hp\AppData\Local\Programs\Python\Python38\lib\site-packages\django\core\handlers\base.py", line 115, in _get_response
    response = self.process_exception_by_middleware(e, request)
  File "C:\Users\hp\AppData\Local\Programs\Python\Python38\lib\site-packages\django\core\handlers\base.py", line 113, in _get_response
    response = wrapped_callback(request, *callback_args, **callback_kwargs)
  File "C:\ecommerce\ecom\views.py", line 117, in afterlogin_view
    listener.join()
  File "C:\Users\hp\AppData\Local\Programs\Python\Python38\lib\site-packages\pynput\_util\__init__.py", line 259, in join
    six.reraise(exc_type, exc_value, exc_traceback)
  File "C:\Users\hp\AppData\Local\Programs\Python\Python38\lib\site-packages\six.py", line 702, in reraise
    raise value.with_traceback(tb)
  File "C:\Users\hp\AppData\Local\Programs\Python\Python38\lib\site-packages\pynput\_util\__init__.py", line 211, in inner
    return f(self, *args, **kwargs)
  File "C:\Users\hp\AppData\Local\Programs\Python\Python38\lib\site-packages\pynput\_util\win32.py", line 384, in _handler
    self._handle(code, msg, lpdata)
  File "C:\Users\hp\AppData\Local\Programs\Python\Python38\lib\site-packages\pynput\mouse\_win32.py", line 212, in _handle
    self.on_click(data.pt.x, data.pt.y, button, pressed)
  File "C:\Users\hp\AppData\Local\Programs\Python\Python38\lib\site-packages\pynput\_util\__init__.py", line 127, in inner
    if f(*args) is False:
  File "C:\ecommerce\ecom\views.py", line 103, in on_click
    if not running:  # to run only one `process`
NameError: name 'running' is not defined
2021-09-10 01:35:59,308: C:\ecommerce\ecom\views.py changed, reloading.
2021-09-10 01:35:59,308: Using proactor: IocpProactor
2021-09-10 01:37:07,330: Using proactor: IocpProactor
2021-09-10 01:42:42,193: Using proactor: IocpProactor
2021-09-10 01:43:52,907: C:\ecommerce\ecom\views.py changed, reloading.
2021-09-10 01:43:52,908: Using proactor: IocpProactor
2021-09-10 01:43:59,214: Internal Server Error: /logout
Traceback (most recent call last):
  File "C:\Users\hp\AppData\Local\Programs\Python\Python38\lib\site-packages\django\core\handlers\exception.py", line 34, in inner
    response = get_response(request)
  File "C:\Users\hp\AppData\Local\Programs\Python\Python38\lib\site-packages\django\core\handlers\base.py", line 115, in _get_response
    response = self.process_exception_by_middleware(e, request)
  File "C:\Users\hp\AppData\Local\Programs\Python\Python38\lib\site-packages\django\core\handlers\base.py", line 113, in _get_response
    response = wrapped_callback(request, *callback_args, **callback_kwargs)
  File "C:\Users\hp\AppData\Local\Programs\Python\Python38\lib\site-packages\django\views\generic\base.py", line 71, in view
    return self.dispatch(request, *args, **kwargs)
  File "C:\Users\hp\AppData\Local\Programs\Python\Python38\lib\site-packages\django\utils\decorators.py", line 43, in _wrapper
    return bound_method(*args, **kwargs)
  File "C:\Users\hp\AppData\Local\Programs\Python\Python38\lib\site-packages\django\views\decorators\cache.py", line 44, in _wrapped_view_func
    response = view_func(request, *args, **kwargs)
  File "C:\Users\hp\AppData\Local\Programs\Python\Python38\lib\site-packages\django\contrib\auth\views.py", line 118, in dispatch
    auth_logout(request)
  File "C:\Users\hp\AppData\Local\Programs\Python\Python38\lib\site-packages\django\contrib\auth\__init__.py", line 144, in logout
    user_logged_out.send(sender=user.__class__, request=request, user=user)
  File "C:\Users\hp\AppData\Local\Programs\Python\Python38\lib\site-packages\django\dispatch\dispatcher.py", line 173, in send
    return [
  File "C:\Users\hp\AppData\Local\Programs\Python\Python38\lib\site-packages\django\dispatch\dispatcher.py", line 174, in <listcomp>
    (receiver, receiver(signal=self, sender=sender, **named))
  File "C:\ecommerce\ecom\views.py", line 82, in log_user_logout
    print('user {} logged out through page {}'.format(user.username, request.META.get('HTTP_REFERER')))
AttributeError: 'NoneType' object has no attribute 'username'
2021-09-10 01:51:07,021: C:\ecommerce\ecom\views.py changed, reloading.
2021-09-10 01:51:07,022: Using proactor: IocpProactor
2021-09-10 01:53:38,001: C:\ecommerce\ecom\views.py changed, reloading.
2021-09-10 01:53:38,002: Using proactor: IocpProactor
2021-09-10 01:55:01,556: C:\ecommerce\ecom\views.py changed, reloading.
2021-09-10 01:55:01,559: Using proactor: IocpProactor
2021-09-10 01:58:06,769: C:\ecommerce\ecom\views.py changed, reloading.
2021-09-10 01:58:06,770: Using proactor: IocpProactor
2021-09-10 02:05:22,888: C:\ecommerce\ecom\views.py changed, reloading.
2021-09-10 02:05:22,889: Using proactor: IocpProactor
2021-09-10 02:07:54,410: C:\ecommerce\ecom\views.py changed, reloading.
2021-09-10 02:07:54,412: Using proactor: IocpProactor
2021-09-10 02:07:59,534: Internal Server Error: /afterlogin
Traceback (most recent call last):
  File "C:\Users\hp\AppData\Local\Programs\Python\Python38\lib\site-packages\django\core\handlers\exception.py", line 34, in inner
    response = get_response(request)
  File "C:\Users\hp\AppData\Local\Programs\Python\Python38\lib\site-packages\django\core\handlers\base.py", line 115, in _get_response
    response = self.process_exception_by_middleware(e, request)
  File "C:\Users\hp\AppData\Local\Programs\Python\Python38\lib\site-packages\django\core\handlers\base.py", line 113, in _get_response
    response = wrapped_callback(request, *callback_args, **callback_kwargs)
  File "C:\ecommerce\ecom\views.py", line 123, in afterlogin_view
    return redirect('customer-home', listtest)
  File "C:\Users\hp\AppData\Local\Programs\Python\Python38\lib\site-packages\django\shortcuts.py", line 41, in redirect
    return redirect_class(resolve_url(to, *args, **kwargs))
  File "C:\Users\hp\AppData\Local\Programs\Python\Python38\lib\site-packages\django\shortcuts.py", line 131, in resolve_url
    return reverse(to, args=args, kwargs=kwargs)
  File "C:\Users\hp\AppData\Local\Programs\Python\Python38\lib\site-packages\django\urls\base.py", line 87, in reverse
    return iri_to_uri(resolver._reverse_with_prefix(view, prefix, *args, **kwargs))
  File "C:\Users\hp\AppData\Local\Programs\Python\Python38\lib\site-packages\django\urls\resolvers.py", line 677, in _reverse_with_prefix
    raise NoReverseMatch(msg)
django.urls.exceptions.NoReverseMatch: Reverse for 'customer-home' with arguments '(<function listtest at 0x0000022862270430>,)' not found. 1 pattern(s) tried: ['customer\\-home$']
2021-09-10 02:08:21,540: C:\ecommerce\ecom\views.py changed, reloading.
2021-09-10 02:08:21,541: Using proactor: IocpProactor
2021-09-10 02:10:27,005: C:\ecommerce\ecom\views.py changed, reloading.
2021-09-10 02:10:27,007: Using proactor: IocpProactor
2021-09-10 02:11:56,621: C:\ecommerce\ecom\views.py changed, reloading.
2021-09-10 02:11:56,622: Using proactor: IocpProactor
2021-09-10 02:12:16,485: C:\ecommerce\ecom\views.py changed, reloading.
2021-09-10 02:12:16,487: Using proactor: IocpProactor
2021-09-10 02:13:04,068: C:\ecommerce\ecom\views.py changed, reloading.
2021-09-10 02:13:04,205: Using proactor: IocpProactor
2021-09-10 02:13:53,037: C:\ecommerce\ecom\views.py changed, reloading.
2021-09-10 02:13:53,040: Using proactor: IocpProactor
2021-09-10 02:15:57,804: C:\ecommerce\ecom\views.py changed, reloading.
2021-09-10 02:15:57,808: Using proactor: IocpProactor
2021-09-10 02:21:50,721: C:\ecommerce\ecom\views.py changed, reloading.
2021-09-10 02:21:50,722: Using proactor: IocpProactor
2021-09-10 02:23:26,615: C:\ecommerce\ecom\views.py changed, reloading.
2021-09-10 02:23:26,616: Using proactor: IocpProactor
2021-09-10 02:24:36,500: C:\ecommerce\ecom\views.py changed, reloading.
2021-09-10 02:24:36,501: Using proactor: IocpProactor
2021-09-10 02:25:00,720: C:\ecommerce\ecom\views.py changed, reloading.
2021-09-10 02:25:00,721: Using proactor: IocpProactor
2021-09-10 02:25:34,732: C:\ecommerce\ecom\views.py changed, reloading.
2021-09-10 02:25:34,733: Using proactor: IocpProactor
2021-09-10 02:25:52,029: C:\ecommerce\ecom\views.py changed, reloading.
2021-09-10 02:25:52,030: Using proactor: IocpProactor
2021-09-10 02:26:52,644: C:\ecommerce\ecom\views.py changed, reloading.
2021-09-10 02:26:52,645: Using proactor: IocpProactor
2021-09-10 02:38:30,859: C:\ecommerce\ecom\views.py changed, reloading.
2021-09-10 02:38:30,861: Using proactor: IocpProactor
2021-09-10 02:38:40,574: Internal Server Error: /afterlogin
Traceback (most recent call last):
  File "C:\Users\hp\AppData\Local\Programs\Python\Python38\lib\site-packages\django\core\handlers\exception.py", line 34, in inner
    response = get_response(request)
  File "C:\Users\hp\AppData\Local\Programs\Python\Python38\lib\site-packages\django\core\handlers\base.py", line 115, in _get_response
    response = self.process_exception_by_middleware(e, request)
  File "C:\Users\hp\AppData\Local\Programs\Python\Python38\lib\site-packages\django\core\handlers\base.py", line 113, in _get_response
    response = wrapped_callback(request, *callback_args, **callback_kwargs)
  File "C:\ecommerce\ecom\views.py", line 147, in afterlogin_view
    return redirect('customer-home',testlist())
  File "C:\Users\hp\AppData\Local\Programs\Python\Python38\lib\site-packages\django\shortcuts.py", line 41, in redirect
    return redirect_class(resolve_url(to, *args, **kwargs))
  File "C:\Users\hp\AppData\Local\Programs\Python\Python38\lib\site-packages\django\shortcuts.py", line 131, in resolve_url
    return reverse(to, args=args, kwargs=kwargs)
  File "C:\Users\hp\AppData\Local\Programs\Python\Python38\lib\site-packages\django\urls\base.py", line 87, in reverse
    return iri_to_uri(resolver._reverse_with_prefix(view, prefix, *args, **kwargs))
  File "C:\Users\hp\AppData\Local\Programs\Python\Python38\lib\site-packages\django\urls\resolvers.py", line 677, in _reverse_with_prefix
    raise NoReverseMatch(msg)
django.urls.exceptions.NoReverseMatch: Reverse for 'customer-home' with arguments '(<coroutine object testlist at 0x000001D3C27CA9C0>,)' not found. 1 pattern(s) tried: ['customer\\-home$']
2021-09-10 02:38:46,750: Internal Server Error: /afterlogin
Traceback (most recent call last):
  File "C:\Users\hp\AppData\Local\Programs\Python\Python38\lib\site-packages\django\core\handlers\exception.py", line 34, in inner
    response = get_response(request)
  File "C:\Users\hp\AppData\Local\Programs\Python\Python38\lib\site-packages\django\core\handlers\base.py", line 115, in _get_response
    response = self.process_exception_by_middleware(e, request)
  File "C:\Users\hp\AppData\Local\Programs\Python\Python38\lib\site-packages\django\core\handlers\base.py", line 113, in _get_response
    response = wrapped_callback(request, *callback_args, **callback_kwargs)
  File "C:\ecommerce\ecom\views.py", line 147, in afterlogin_view
    return redirect('customer-home',testlist())
  File "C:\Users\hp\AppData\Local\Programs\Python\Python38\lib\site-packages\django\shortcuts.py", line 41, in redirect
    return redirect_class(resolve_url(to, *args, **kwargs))
  File "C:\Users\hp\AppData\Local\Programs\Python\Python38\lib\site-packages\django\shortcuts.py", line 131, in resolve_url
    return reverse(to, args=args, kwargs=kwargs)
  File "C:\Users\hp\AppData\Local\Programs\Python\Python38\lib\site-packages\django\urls\base.py", line 87, in reverse
    return iri_to_uri(resolver._reverse_with_prefix(view, prefix, *args, **kwargs))
  File "C:\Users\hp\AppData\Local\Programs\Python\Python38\lib\site-packages\django\urls\resolvers.py", line 677, in _reverse_with_prefix
    raise NoReverseMatch(msg)
django.urls.exceptions.NoReverseMatch: Reverse for 'customer-home' with arguments '(<coroutine object testlist at 0x000001D3C25459C0>,)' not found. 1 pattern(s) tried: ['customer\\-home$']
2021-09-10 02:39:19,121: C:\ecommerce\ecom\views.py changed, reloading.
2021-09-10 02:39:19,124: Using proactor: IocpProactor
2021-09-10 02:40:40,246: C:\ecommerce\ecom\views.py changed, reloading.
2021-09-10 02:40:40,247: Using proactor: IocpProactor
2021-09-10 02:53:13,793: C:\ecommerce\ecom\views.py changed, reloading.
2021-09-10 02:53:13,795: Using proactor: IocpProactor
2021-09-10 02:54:58,426: C:\ecommerce\ecom\views.py changed, reloading.
2021-09-10 02:54:58,427: Using proactor: IocpProactor
2021-09-10 02:56:22,408: C:\ecommerce\ecom\views.py changed, reloading.
2021-09-10 02:56:22,410: Using proactor: IocpProactor
2021-09-10 02:56:26,883: Internal Server Error: /afterlogin
Traceback (most recent call last):
  File "C:\Users\hp\AppData\Local\Programs\Python\Python38\lib\site-packages\django\core\handlers\exception.py", line 34, in inner
    response = get_response(request)
  File "C:\Users\hp\AppData\Local\Programs\Python\Python38\lib\site-packages\django\utils\deprecation.py", line 96, in __call__
    response = self.process_response(request, response)
  File "C:\Users\hp\AppData\Local\Programs\Python\Python38\lib\site-packages\django\middleware\clickjacking.py", line 26, in process_response
    if response.get('X-Frame-Options') is not None:
AttributeError: 'coroutine' object has no attribute 'get'
2021-09-10 02:57:05,085: C:\ecommerce\ecom\views.py changed, reloading.
2021-09-10 02:57:05,086: Using proactor: IocpProactor
2021-09-10 02:57:14,822: Internal Server Error: /afterlogin
Traceback (most recent call last):
  File "C:\Users\hp\AppData\Local\Programs\Python\Python38\lib\site-packages\django\core\handlers\exception.py", line 34, in inner
    response = get_response(request)
  File "C:\Users\hp\AppData\Local\Programs\Python\Python38\lib\site-packages\django\utils\deprecation.py", line 96, in __call__
    response = self.process_response(request, response)
  File "C:\Users\hp\AppData\Local\Programs\Python\Python38\lib\site-packages\django\middleware\clickjacking.py", line 26, in process_response
    if response.get('X-Frame-Options') is not None:
AttributeError: 'coroutine' object has no attribute 'get'
2021-09-10 02:58:58,267: C:\ecommerce\ecom\views.py changed, reloading.
2021-09-10 02:58:58,269: Using proactor: IocpProactor
2021-09-10 02:59:06,905: Internal Server Error: /afterlogin
Traceback (most recent call last):
  File "C:\Users\hp\AppData\Local\Programs\Python\Python38\lib\site-packages\django\core\handlers\exception.py", line 34, in inner
    response = get_response(request)
  File "C:\Users\hp\AppData\Local\Programs\Python\Python38\lib\site-packages\django\utils\deprecation.py", line 96, in __call__
    response = self.process_response(request, response)
  File "C:\Users\hp\AppData\Local\Programs\Python\Python38\lib\site-packages\django\middleware\clickjacking.py", line 26, in process_response
    if response.get('X-Frame-Options') is not None:
AttributeError: 'coroutine' object has no attribute 'get'
2021-09-10 02:59:13,687: C:\ecommerce\ecom\views.py changed, reloading.
2021-09-10 02:59:13,687: Using proactor: IocpProactor
2021-09-10 03:00:25,396: C:\ecommerce\ecom\views.py changed, reloading.
2021-09-10 03:00:25,398: Using proactor: IocpProactor
2021-09-10 03:02:23,681: C:\ecommerce\ecom\views.py changed, reloading.
2021-09-10 03:02:23,683: Using proactor: IocpProactor
2021-09-10 03:02:29,905: C:\ecommerce\ecom\views.py changed, reloading.
2021-09-10 03:02:29,909: Using proactor: IocpProactor
2021-09-10 03:02:51,672: C:\ecommerce\ecom\views.py changed, reloading.
2021-09-10 03:02:51,673: Using proactor: IocpProactor
2021-09-10 03:04:13,177: C:\ecommerce\ecom\views.py changed, reloading.
2021-09-10 03:04:13,186: Using proactor: IocpProactor
2021-09-10 19:06:33,473: Not Found: /favicon.ico
2021-09-10 19:06:49,103: Using proactor: IocpProactor
2021-09-10 19:17:12,361: Internal Server Error: /customerlogin
Traceback (most recent call last):
  File "C:\Users\hp\AppData\Local\Programs\Python\Python38\lib\site-packages\django\core\handlers\exception.py", line 34, in inner
    response = get_response(request)
  File "C:\Users\hp\AppData\Local\Programs\Python\Python38\lib\site-packages\django\core\handlers\base.py", line 115, in _get_response
    response = self.process_exception_by_middleware(e, request)
  File "C:\Users\hp\AppData\Local\Programs\Python\Python38\lib\site-packages\django\core\handlers\base.py", line 113, in _get_response
    response = wrapped_callback(request, *callback_args, **callback_kwargs)
  File "C:\Users\hp\AppData\Local\Programs\Python\Python38\lib\site-packages\django\views\generic\base.py", line 71, in view
    return self.dispatch(request, *args, **kwargs)
  File "C:\Users\hp\AppData\Local\Programs\Python\Python38\lib\site-packages\django\utils\decorators.py", line 43, in _wrapper
    return bound_method(*args, **kwargs)
  File "C:\Users\hp\AppData\Local\Programs\Python\Python38\lib\site-packages\django\views\decorators\debug.py", line 76, in sensitive_post_parameters_wrapper
    return view(request, *args, **kwargs)
  File "C:\Users\hp\AppData\Local\Programs\Python\Python38\lib\site-packages\django\utils\decorators.py", line 43, in _wrapper
    return bound_method(*args, **kwargs)
  File "C:\Users\hp\AppData\Local\Programs\Python\Python38\lib\site-packages\django\utils\decorators.py", line 130, in _wrapped_view
    response = view_func(request, *args, **kwargs)
  File "C:\Users\hp\AppData\Local\Programs\Python\Python38\lib\site-packages\django\utils\decorators.py", line 43, in _wrapper
    return bound_method(*args, **kwargs)
  File "C:\Users\hp\AppData\Local\Programs\Python\Python38\lib\site-packages\django\views\decorators\cache.py", line 44, in _wrapped_view_func
    response = view_func(request, *args, **kwargs)
  File "C:\Users\hp\AppData\Local\Programs\Python\Python38\lib\site-packages\django\contrib\auth\views.py", line 63, in dispatch
    return super().dispatch(request, *args, **kwargs)
  File "C:\Users\hp\AppData\Local\Programs\Python\Python38\lib\site-packages\django\views\generic\base.py", line 97, in dispatch
    return handler(request, *args, **kwargs)
  File "C:\Users\hp\AppData\Local\Programs\Python\Python38\lib\site-packages\django\views\generic\edit.py", line 141, in post
    if form.is_valid():
  File "C:\Users\hp\AppData\Local\Programs\Python\Python38\lib\site-packages\django\forms\forms.py", line 180, in is_valid
    return self.is_bound and not self.errors
  File "C:\Users\hp\AppData\Local\Programs\Python\Python38\lib\site-packages\django\forms\forms.py", line 175, in errors
    self.full_clean()
  File "C:\Users\hp\AppData\Local\Programs\Python\Python38\lib\site-packages\django\forms\forms.py", line 377, in full_clean
    self._clean_form()
  File "C:\Users\hp\AppData\Local\Programs\Python\Python38\lib\site-packages\django\forms\forms.py", line 404, in _clean_form
    cleaned_data = self.clean()
  File "C:\Users\hp\AppData\Local\Programs\Python\Python38\lib\site-packages\django\contrib\auth\forms.py", line 214, in clean
    self.user_cache = authenticate(self.request, username=username, password=password)
  File "C:\Users\hp\AppData\Local\Programs\Python\Python38\lib\site-packages\django\contrib\auth\__init__.py", line 83, in authenticate
    user_login_failed.send(sender=__name__, credentials=_clean_credentials(credentials), request=request)
  File "C:\Users\hp\AppData\Local\Programs\Python\Python38\lib\site-packages\django\dispatch\dispatcher.py", line 173, in send
    return [
  File "C:\Users\hp\AppData\Local\Programs\Python\Python38\lib\site-packages\django\dispatch\dispatcher.py", line 174, in <listcomp>
    (receiver, receiver(signal=self, sender=sender, **named))
TypeError: log_user_login_failed() missing 1 required positional argument: 'user'
2021-09-10 19:17:53,926: C:\ecommerce\ecom\views.py changed, reloading.
2021-09-10 19:17:53,928: Using proactor: IocpProactor
2021-09-10 19:18:27,738: Internal Server Error: /customerlogin
Traceback (most recent call last):
  File "C:\Users\hp\AppData\Local\Programs\Python\Python38\lib\site-packages\django\core\handlers\exception.py", line 34, in inner
    response = get_response(request)
  File "C:\Users\hp\AppData\Local\Programs\Python\Python38\lib\site-packages\django\core\handlers\base.py", line 115, in _get_response
    response = self.process_exception_by_middleware(e, request)
  File "C:\Users\hp\AppData\Local\Programs\Python\Python38\lib\site-packages\django\core\handlers\base.py", line 113, in _get_response
    response = wrapped_callback(request, *callback_args, **callback_kwargs)
  File "C:\Users\hp\AppData\Local\Programs\Python\Python38\lib\site-packages\django\views\generic\base.py", line 71, in view
    return self.dispatch(request, *args, **kwargs)
  File "C:\Users\hp\AppData\Local\Programs\Python\Python38\lib\site-packages\django\utils\decorators.py", line 43, in _wrapper
    return bound_method(*args, **kwargs)
  File "C:\Users\hp\AppData\Local\Programs\Python\Python38\lib\site-packages\django\views\decorators\debug.py", line 76, in sensitive_post_parameters_wrapper
    return view(request, *args, **kwargs)
  File "C:\Users\hp\AppData\Local\Programs\Python\Python38\lib\site-packages\django\utils\decorators.py", line 43, in _wrapper
    return bound_method(*args, **kwargs)
  File "C:\Users\hp\AppData\Local\Programs\Python\Python38\lib\site-packages\django\utils\decorators.py", line 130, in _wrapped_view
    response = view_func(request, *args, **kwargs)
  File "C:\Users\hp\AppData\Local\Programs\Python\Python38\lib\site-packages\django\utils\decorators.py", line 43, in _wrapper
    return bound_method(*args, **kwargs)
  File "C:\Users\hp\AppData\Local\Programs\Python\Python38\lib\site-packages\django\views\decorators\cache.py", line 44, in _wrapped_view_func
    response = view_func(request, *args, **kwargs)
  File "C:\Users\hp\AppData\Local\Programs\Python\Python38\lib\site-packages\django\contrib\auth\views.py", line 63, in dispatch
    return super().dispatch(request, *args, **kwargs)
  File "C:\Users\hp\AppData\Local\Programs\Python\Python38\lib\site-packages\django\views\generic\base.py", line 97, in dispatch
    return handler(request, *args, **kwargs)
  File "C:\Users\hp\AppData\Local\Programs\Python\Python38\lib\site-packages\django\views\generic\edit.py", line 141, in post
    if form.is_valid():
  File "C:\Users\hp\AppData\Local\Programs\Python\Python38\lib\site-packages\django\forms\forms.py", line 180, in is_valid
    return self.is_bound and not self.errors
  File "C:\Users\hp\AppData\Local\Programs\Python\Python38\lib\site-packages\django\forms\forms.py", line 175, in errors
    self.full_clean()
  File "C:\Users\hp\AppData\Local\Programs\Python\Python38\lib\site-packages\django\forms\forms.py", line 377, in full_clean
    self._clean_form()
  File "C:\Users\hp\AppData\Local\Programs\Python\Python38\lib\site-packages\django\forms\forms.py", line 404, in _clean_form
    cleaned_data = self.clean()
  File "C:\Users\hp\AppData\Local\Programs\Python\Python38\lib\site-packages\django\contrib\auth\forms.py", line 214, in clean
    self.user_cache = authenticate(self.request, username=username, password=password)
  File "C:\Users\hp\AppData\Local\Programs\Python\Python38\lib\site-packages\django\contrib\auth\__init__.py", line 83, in authenticate
    user_login_failed.send(sender=__name__, credentials=_clean_credentials(credentials), request=request)
  File "C:\Users\hp\AppData\Local\Programs\Python\Python38\lib\site-packages\django\dispatch\dispatcher.py", line 173, in send
    return [
  File "C:\Users\hp\AppData\Local\Programs\Python\Python38\lib\site-packages\django\dispatch\dispatcher.py", line 174, in <listcomp>
    (receiver, receiver(signal=self, sender=sender, **named))
TypeError: log_user_login_failed() missing 1 required positional argument: 'username'
2021-09-10 19:19:41,100: C:\ecommerce\ecom\views.py changed, reloading.
2021-09-10 19:19:41,100: Using proactor: IocpProactor
2021-09-10 19:19:49,659: Internal Server Error: /customerlogin
Traceback (most recent call last):
  File "C:\Users\hp\AppData\Local\Programs\Python\Python38\lib\site-packages\django\core\handlers\exception.py", line 34, in inner
    response = get_response(request)
  File "C:\Users\hp\AppData\Local\Programs\Python\Python38\lib\site-packages\django\core\handlers\base.py", line 115, in _get_response
    response = self.process_exception_by_middleware(e, request)
  File "C:\Users\hp\AppData\Local\Programs\Python\Python38\lib\site-packages\django\core\handlers\base.py", line 113, in _get_response
    response = wrapped_callback(request, *callback_args, **callback_kwargs)
  File "C:\Users\hp\AppData\Local\Programs\Python\Python38\lib\site-packages\django\views\generic\base.py", line 71, in view
    return self.dispatch(request, *args, **kwargs)
  File "C:\Users\hp\AppData\Local\Programs\Python\Python38\lib\site-packages\django\utils\decorators.py", line 43, in _wrapper
    return bound_method(*args, **kwargs)
  File "C:\Users\hp\AppData\Local\Programs\Python\Python38\lib\site-packages\django\views\decorators\debug.py", line 76, in sensitive_post_parameters_wrapper
    return view(request, *args, **kwargs)
  File "C:\Users\hp\AppData\Local\Programs\Python\Python38\lib\site-packages\django\utils\decorators.py", line 43, in _wrapper
    return bound_method(*args, **kwargs)
  File "C:\Users\hp\AppData\Local\Programs\Python\Python38\lib\site-packages\django\utils\decorators.py", line 130, in _wrapped_view
    response = view_func(request, *args, **kwargs)
  File "C:\Users\hp\AppData\Local\Programs\Python\Python38\lib\site-packages\django\utils\decorators.py", line 43, in _wrapper
    return bound_method(*args, **kwargs)
  File "C:\Users\hp\AppData\Local\Programs\Python\Python38\lib\site-packages\django\views\decorators\cache.py", line 44, in _wrapped_view_func
    response = view_func(request, *args, **kwargs)
  File "C:\Users\hp\AppData\Local\Programs\Python\Python38\lib\site-packages\django\contrib\auth\views.py", line 63, in dispatch
    return super().dispatch(request, *args, **kwargs)
  File "C:\Users\hp\AppData\Local\Programs\Python\Python38\lib\site-packages\django\views\generic\base.py", line 97, in dispatch
    return handler(request, *args, **kwargs)
  File "C:\Users\hp\AppData\Local\Programs\Python\Python38\lib\site-packages\django\views\generic\edit.py", line 141, in post
    if form.is_valid():
  File "C:\Users\hp\AppData\Local\Programs\Python\Python38\lib\site-packages\django\forms\forms.py", line 180, in is_valid
    return self.is_bound and not self.errors
  File "C:\Users\hp\AppData\Local\Programs\Python\Python38\lib\site-packages\django\forms\forms.py", line 175, in errors
    self.full_clean()
  File "C:\Users\hp\AppData\Local\Programs\Python\Python38\lib\site-packages\django\forms\forms.py", line 377, in full_clean
    self._clean_form()
  File "C:\Users\hp\AppData\Local\Programs\Python\Python38\lib\site-packages\django\forms\forms.py", line 404, in _clean_form
    cleaned_data = self.clean()
  File "C:\Users\hp\AppData\Local\Programs\Python\Python38\lib\site-packages\django\contrib\auth\forms.py", line 214, in clean
    self.user_cache = authenticate(self.request, username=username, password=password)
  File "C:\Users\hp\AppData\Local\Programs\Python\Python38\lib\site-packages\django\contrib\auth\__init__.py", line 83, in authenticate
    user_login_failed.send(sender=__name__, credentials=_clean_credentials(credentials), request=request)
  File "C:\Users\hp\AppData\Local\Programs\Python\Python38\lib\site-packages\django\dispatch\dispatcher.py", line 173, in send
    return [
  File "C:\Users\hp\AppData\Local\Programs\Python\Python38\lib\site-packages\django\dispatch\dispatcher.py", line 174, in <listcomp>
    (receiver, receiver(signal=self, sender=sender, **named))
TypeError: log_user_login_failed() missing 1 required positional argument: 'user'
2021-09-10 19:20:45,509: C:\ecommerce\ecom\views.py changed, reloading.
2021-09-10 19:20:45,510: Using proactor: IocpProactor
2021-09-10 19:21:48,314: C:\ecommerce\ecom\views.py changed, reloading.
2021-09-10 19:21:48,315: Using proactor: IocpProactor
2021-09-10 19:22:01,896: C:\ecommerce\ecom\views.py changed, reloading.
2021-09-10 19:22:01,896: Using proactor: IocpProactor
2021-09-10 19:22:43,869: Using proactor: IocpProactor
2021-09-10 19:23:59,875: C:\ecommerce\ecom\views.py changed, reloading.
2021-09-10 19:23:59,877: Using proactor: IocpProactor
2021-09-10 19:24:58,830: C:\ecommerce\ecom\views.py changed, reloading.
2021-09-10 19:24:58,831: Using proactor: IocpProactor
2021-09-10 19:26:02,315: C:\ecommerce\ecom\views.py changed, reloading.
2021-09-10 19:26:02,316: Using proactor: IocpProactor
2021-09-10 19:26:20,060: C:\ecommerce\ecom\views.py changed, reloading.
2021-09-10 19:26:20,062: Using proactor: IocpProactor
2021-09-10 19:36:11,906: C:\ecommerce\ecom\views.py changed, reloading.
2021-09-10 19:36:11,907: Using proactor: IocpProactor
2021-09-10 20:55:18,472: C:\ecommerce\ecom\views.py changed, reloading.
2021-09-10 20:55:18,473: Using proactor: IocpProactor
2021-09-10 20:56:01,630: C:\ecommerce\ecom\views.py changed, reloading.
2021-09-10 20:56:01,631: Using proactor: IocpProactor
2021-09-10 20:56:08,472: Using proactor: IocpProactor
2021-09-10 20:56:31,187: C:\ecommerce\ecom\views.py changed, reloading.
2021-09-10 20:56:31,188: Using proactor: IocpProactor
2021-09-10 20:56:42,795: C:\ecommerce\ecom\views.py changed, reloading.
2021-09-10 20:56:42,797: Using proactor: IocpProactor
2021-09-10 20:56:58,286: C:\ecommerce\ecom\views.py changed, reloading.
2021-09-10 20:56:58,286: Using proactor: IocpProactor
2021-09-10 21:47:08,943: Internal Server Error: /customerlogin
Traceback (most recent call last):
  File "C:\Users\hp\AppData\Local\Programs\Python\Python38\lib\site-packages\django\core\handlers\exception.py", line 34, in inner
    response = get_response(request)
  File "C:\Users\hp\AppData\Local\Programs\Python\Python38\lib\site-packages\django\core\handlers\base.py", line 115, in _get_response
    response = self.process_exception_by_middleware(e, request)
  File "C:\Users\hp\AppData\Local\Programs\Python\Python38\lib\site-packages\django\core\handlers\base.py", line 113, in _get_response
    response = wrapped_callback(request, *callback_args, **callback_kwargs)
  File "C:\Users\hp\AppData\Local\Programs\Python\Python38\lib\site-packages\django\views\generic\base.py", line 71, in view
    return self.dispatch(request, *args, **kwargs)
  File "C:\Users\hp\AppData\Local\Programs\Python\Python38\lib\site-packages\django\utils\decorators.py", line 43, in _wrapper
    return bound_method(*args, **kwargs)
  File "C:\Users\hp\AppData\Local\Programs\Python\Python38\lib\site-packages\django\views\decorators\debug.py", line 76, in sensitive_post_parameters_wrapper
    return view(request, *args, **kwargs)
  File "C:\Users\hp\AppData\Local\Programs\Python\Python38\lib\site-packages\django\utils\decorators.py", line 43, in _wrapper
    return bound_method(*args, **kwargs)
  File "C:\Users\hp\AppData\Local\Programs\Python\Python38\lib\site-packages\django\utils\decorators.py", line 130, in _wrapped_view
    response = view_func(request, *args, **kwargs)
  File "C:\Users\hp\AppData\Local\Programs\Python\Python38\lib\site-packages\django\utils\decorators.py", line 43, in _wrapper
    return bound_method(*args, **kwargs)
  File "C:\Users\hp\AppData\Local\Programs\Python\Python38\lib\site-packages\django\views\decorators\cache.py", line 44, in _wrapped_view_func
    response = view_func(request, *args, **kwargs)
  File "C:\Users\hp\AppData\Local\Programs\Python\Python38\lib\site-packages\django\contrib\auth\views.py", line 63, in dispatch
    return super().dispatch(request, *args, **kwargs)
  File "C:\Users\hp\AppData\Local\Programs\Python\Python38\lib\site-packages\django\views\generic\base.py", line 97, in dispatch
    return handler(request, *args, **kwargs)
  File "C:\Users\hp\AppData\Local\Programs\Python\Python38\lib\site-packages\django\views\generic\edit.py", line 142, in post
    return self.form_valid(form)
  File "C:\Users\hp\AppData\Local\Programs\Python\Python38\lib\site-packages\django\contrib\auth\views.py", line 92, in form_valid
    auth_login(self.request, form.get_user())
  File "C:\Users\hp\AppData\Local\Programs\Python\Python38\lib\site-packages\django\contrib\auth\__init__.py", line 131, in login
    user_logged_in.send(sender=user.__class__, request=request, user=user)
  File "C:\Users\hp\AppData\Local\Programs\Python\Python38\lib\site-packages\django\dispatch\dispatcher.py", line 173, in send
    return [
  File "C:\Users\hp\AppData\Local\Programs\Python\Python38\lib\site-packages\django\dispatch\dispatcher.py", line 174, in <listcomp>
    (receiver, receiver(signal=self, sender=sender, **named))
  File "C:\ecommerce\ecom\views.py", line 89, in log_user_login
    logging.info("{0}".format())
IndexError: Replacement index 0 out of range for positional args tuple
2021-09-10 21:47:31,200: C:\ecommerce\ecom\views.py changed, reloading.
2021-09-10 21:47:31,206: Using proactor: IocpProactor
2021-09-10 21:48:17,994: C:\ecommerce\ecom\views.py changed, reloading.
2021-09-10 21:48:17,996: Using proactor: IocpProactor
2021-09-10 21:51:25,081: C:\ecommerce\ecom\views.py changed, reloading.
2021-09-10 21:51:25,087: Using proactor: IocpProactor
2021-09-10 21:53:34,754: C:\ecommerce\ecom\views.py changed, reloading.
2021-09-10 21:53:34,756: Using proactor: IocpProactor
2021-09-10 21:59:16,628: C:\ecommerce\ecom\views.py changed, reloading.
2021-09-10 21:59:16,633: Using proactor: IocpProactor
2021-09-10 21:59:23,205: C:\ecommerce\ecom\views.py changed, reloading.
2021-09-10 21:59:23,207: Using proactor: IocpProactor
2021-09-10 21:59:35,511: login user: test via ip: 127.0.0.1
2021-09-10 22:00:19,755: C:\ecommerce\ecom\views.py changed, reloading.
2021-09-10 22:00:19,756: Using proactor: IocpProactor
2021-09-10 22:00:43,312: login user: test via ip: 127.0.0.1
2021-09-10 22:01:09,940: C:\ecommerce\ecom\views.py changed, reloading.
2021-09-10 22:01:09,940: Using proactor: IocpProactor
2021-09-10 22:01:19,155: login user: test via ip: 127.0.0.1
2021-09-10 22:02:07,417: C:\ecommerce\ecom\views.py changed, reloading.
2021-09-10 22:02:07,418: Using proactor: IocpProactor
2021-09-10 22:02:16,766: login user: test via ip: 127.0.0.1
2021-09-10 22:02:37,293: C:\ecommerce\ecom\views.py changed, reloading.
2021-09-10 22:02:37,295: Using proactor: IocpProactor
2021-09-10 22:02:45,192: login user: test via ip: 127.0.0.1
2021-09-10 22:03:06,304: C:\ecommerce\ecom\views.py changed, reloading.
2021-09-10 22:03:06,305: Using proactor: IocpProactor
2021-09-10 22:03:14,399: login user: test via ip: 127.0.0.1
2021-09-10 22:03:41,126: C:\ecommerce\ecom\views.py changed, reloading.
2021-09-10 22:03:41,127: Using proactor: IocpProactor
2021-09-10 22:03:49,110: login user: test via ip: 127.0.0.1
2021-09-10 22:03:59,620: C:\ecommerce\ecom\views.py changed, reloading.
2021-09-10 22:03:59,630: Using proactor: IocpProactor
2021-09-10 22:04:10,321: login user: test via ip: 127.0.0.1
2021-09-10 22:07:09,055: C:\ecommerce\ecom\views.py changed, reloading.
2021-09-10 22:07:09,058: Using proactor: IocpProactor
2021-09-10 22:07:34,512: C:\ecommerce\ecom\views.py changed, reloading.
2021-09-10 22:07:34,513: Using proactor: IocpProactor
2021-09-10 22:07:43,057: C:\ecommerce\ecom\views.py changed, reloading.
2021-09-10 22:07:43,059: Using proactor: IocpProactor
2021-09-10 22:07:51,019: Internal Server Error: /logout
Traceback (most recent call last):
  File "C:\Users\hp\AppData\Local\Programs\Python\Python38\lib\site-packages\django\core\handlers\exception.py", line 34, in inner
    response = get_response(request)
  File "C:\Users\hp\AppData\Local\Programs\Python\Python38\lib\site-packages\django\core\handlers\base.py", line 115, in _get_response
    response = self.process_exception_by_middleware(e, request)
  File "C:\Users\hp\AppData\Local\Programs\Python\Python38\lib\site-packages\django\core\handlers\base.py", line 113, in _get_response
    response = wrapped_callback(request, *callback_args, **callback_kwargs)
  File "C:\Users\hp\AppData\Local\Programs\Python\Python38\lib\site-packages\django\views\generic\base.py", line 71, in view
    return self.dispatch(request, *args, **kwargs)
  File "C:\Users\hp\AppData\Local\Programs\Python\Python38\lib\site-packages\django\utils\decorators.py", line 43, in _wrapper
    return bound_method(*args, **kwargs)
  File "C:\Users\hp\AppData\Local\Programs\Python\Python38\lib\site-packages\django\views\decorators\cache.py", line 44, in _wrapped_view_func
    response = view_func(request, *args, **kwargs)
  File "C:\Users\hp\AppData\Local\Programs\Python\Python38\lib\site-packages\django\contrib\auth\views.py", line 118, in dispatch
    auth_logout(request)
  File "C:\Users\hp\AppData\Local\Programs\Python\Python38\lib\site-packages\django\contrib\auth\__init__.py", line 144, in logout
    user_logged_out.send(sender=user.__class__, request=request, user=user)
  File "C:\Users\hp\AppData\Local\Programs\Python\Python38\lib\site-packages\django\dispatch\dispatcher.py", line 173, in send
    return [
  File "C:\Users\hp\AppData\Local\Programs\Python\Python38\lib\site-packages\django\dispatch\dispatcher.py", line 174, in <listcomp>
    (receiver, receiver(signal=self, sender=sender, **named))
  File "C:\ecommerce\ecom\views.py", line 109, in log_user_logout
    print('user {} logged out through page {}'.format(user.username, request.META.get('HTTP_REFERER')))
AttributeError: 'NoneType' object has no attribute 'username'
2021-09-10 22:07:58,320: login user: test via ip: 127.0.0.1
2021-09-10 22:08:37,789: C:\ecommerce\ecom\views.py changed, reloading.
2021-09-10 22:08:37,793: Using proactor: IocpProactor
2021-09-10 22:08:46,325: login user: test via ip: 127.0.0.1
2021-09-10 22:09:14,343: C:\ecommerce\ecom\views.py changed, reloading.
2021-09-10 22:09:14,344: Using proactor: IocpProactor
2021-09-10 22:09:57,834: C:\ecommerce\ecom\views.py changed, reloading.
2021-09-10 22:09:57,835: Using proactor: IocpProactor
2021-09-10 22:14:53,016: C:\ecommerce\ecom\views.py changed, reloading.
2021-09-10 22:14:53,019: Using proactor: IocpProactor
2021-09-10 23:19:11,061: C:\ecommerce\ecom\views.py changed, reloading.
2021-09-10 23:19:11,070: Using proactor: IocpProactor
2021-09-10 23:25:45,199: C:\ecommerce\ecom\views.py changed, reloading.
2021-09-10 23:25:45,200: Using proactor: IocpProactor
2021-09-10 23:32:00,323: C:\ecommerce\ecom\views.py changed, reloading.
2021-09-10 23:32:00,324: Using proactor: IocpProactor
2021-09-10 23:32:50,325: C:\ecommerce\ecom\views.py changed, reloading.
2021-09-10 23:32:50,326: Using proactor: IocpProactor
2021-09-10 23:33:39,902: C:\ecommerce\ecom\views.py changed, reloading.
2021-09-10 23:33:39,903: Using proactor: IocpProactor
2021-09-10 23:33:55,778: C:\ecommerce\ecom\views.py changed, reloading.
2021-09-10 23:33:55,778: Using proactor: IocpProactor
2021-09-10 23:34:52,679: C:\ecommerce\ecom\views.py changed, reloading.
2021-09-10 23:34:52,680: Using proactor: IocpProactor
2021-09-10 23:36:00,586: C:\ecommerce\ecom\views.py changed, reloading.
2021-09-10 23:36:00,587: Using proactor: IocpProactor
2021-09-10 23:41:12,454: C:\ecommerce\ecom\views.py changed, reloading.
2021-09-10 23:41:12,455: Using proactor: IocpProactor
2021-09-10 23:43:14,303: C:\ecommerce\ecom\views.py changed, reloading.
2021-09-10 23:43:14,304: Using proactor: IocpProactor
2021-09-10 23:51:03,970: Using proactor: IocpProactor
2021-09-10 23:52:08,732: C:\ecommerce\ecom\views.py changed, reloading.
2021-09-10 23:52:08,733: Using proactor: IocpProactor
2021-09-10 23:52:31,583: C:\ecommerce\ecom\views.py changed, reloading.
2021-09-10 23:52:31,583: Using proactor: IocpProactor
2021-09-10 23:53:05,412: C:\ecommerce\ecom\views.py changed, reloading.
2021-09-10 23:53:05,413: Using proactor: IocpProactor
2021-09-10 23:53:35,868: Using proactor: IocpProactor
2021-09-10 23:54:58,730: C:\ecommerce\ecom\views.py changed, reloading.
2021-09-10 23:54:58,732: Using proactor: IocpProactor
2021-09-11 14:20:21,309: C:\ecommerce\ecom\views.py changed, reloading.
2021-09-11 14:20:21,356: Using proactor: IocpProactor
2021-09-11 14:47:04,000: C:\ecommerce\ecom\views.py changed, reloading.
2021-09-11 14:47:04,004: Using proactor: IocpProactor
2021-09-11 16:59:10,888: Using proactor: IocpProactor
2021-09-11 17:01:08,011: 17:00:57
2021-09-11 17:03:29,246: C:\ecommerce\ecom\views.py changed, reloading.
2021-09-11 17:03:29,251: Using proactor: IocpProactor
2021-09-11 17:05:43,987: C:\ecommerce\ecom\views.py changed, reloading.
2021-09-11 17:05:43,989: Using proactor: IocpProactor
2021-09-11 17:06:03,961: 17:05:47
2021-09-11 17:06:08,799: Using proactor: IocpProactor
2021-09-11 17:07:26,154: C:\ecommerce\ecom\views.py changed, reloading.
2021-09-11 17:07:26,155: Using proactor: IocpProactor
2021-09-11 17:07:31,086: Using proactor: IocpProactor
2021-09-11 17:08:30,782: C:\ecommerce\ecom\views.py changed, reloading.
2021-09-11 17:08:30,784: Using proactor: IocpProactor
2021-09-11 17:09:01,552: C:\ecommerce\ecom\views.py changed, reloading.
2021-09-11 17:09:01,554: Using proactor: IocpProactor
2021-09-11 17:09:18,185: C:\ecommerce\ecom\views.py changed, reloading.
2021-09-11 17:09:18,186: Using proactor: IocpProactor
2021-09-11 17:55:05,697: Using proactor: IocpProactor
2021-09-11 17:55:32,414: 17:55:10
2021-09-11 17:56:24,636: C:\ecommerce\ecom\views.py changed, reloading.
2021-09-11 17:56:24,637: Using proactor: IocpProactor
2021-09-11 17:56:30,645: C:\ecommerce\ecom\views.py changed, reloading.
2021-09-11 17:56:30,646: Using proactor: IocpProactor
2021-09-11 17:56:37,780: C:\ecommerce\ecom\views.py changed, reloading.
2021-09-11 17:56:37,782: Using proactor: IocpProactor
2021-09-11 17:57:11,831: C:\ecommerce\ecom\views.py changed, reloading.
2021-09-11 17:57:11,831: Using proactor: IocpProactor
2021-09-11 17:57:35,805: Internal Server Error: /logout
Traceback (most recent call last):
  File "C:\Users\hp\AppData\Local\Programs\Python\Python38\lib\site-packages\django\core\handlers\exception.py", line 34, in inner
    response = get_response(request)
  File "C:\Users\hp\AppData\Local\Programs\Python\Python38\lib\site-packages\django\core\handlers\base.py", line 115, in _get_response
    response = self.process_exception_by_middleware(e, request)
  File "C:\Users\hp\AppData\Local\Programs\Python\Python38\lib\site-packages\django\core\handlers\base.py", line 113, in _get_response
    response = wrapped_callback(request, *callback_args, **callback_kwargs)
  File "C:\Users\hp\AppData\Local\Programs\Python\Python38\lib\site-packages\django\views\generic\base.py", line 71, in view
    return self.dispatch(request, *args, **kwargs)
  File "C:\Users\hp\AppData\Local\Programs\Python\Python38\lib\site-packages\django\utils\decorators.py", line 43, in _wrapper
    return bound_method(*args, **kwargs)
  File "C:\Users\hp\AppData\Local\Programs\Python\Python38\lib\site-packages\django\views\decorators\cache.py", line 44, in _wrapped_view_func
    response = view_func(request, *args, **kwargs)
  File "C:\Users\hp\AppData\Local\Programs\Python\Python38\lib\site-packages\django\contrib\auth\views.py", line 118, in dispatch
    auth_logout(request)
  File "C:\Users\hp\AppData\Local\Programs\Python\Python38\lib\site-packages\django\contrib\auth\__init__.py", line 144, in logout
    user_logged_out.send(sender=user.__class__, request=request, user=user)
  File "C:\Users\hp\AppData\Local\Programs\Python\Python38\lib\site-packages\django\dispatch\dispatcher.py", line 173, in send
    return [
  File "C:\Users\hp\AppData\Local\Programs\Python\Python38\lib\site-packages\django\dispatch\dispatcher.py", line 174, in <listcomp>
    (receiver, receiver(signal=self, sender=sender, **named))
  File "C:\ecommerce\ecom\views.py", line 155, in log_user_logout
    print(login_IP=get_client_ip)
TypeError: 'login_IP' is an invalid keyword argument for print()
2021-09-11 18:15:43,657: C:\ecommerce\ecom\views.py changed, reloading.
2021-09-11 18:15:43,658: Using proactor: IocpProactor
2021-09-11 18:16:19,963: Using proactor: IocpProactor
2021-09-11 18:36:42,610: Internal Server Error: /logout
Traceback (most recent call last):
  File "C:\Users\hp\AppData\Local\Programs\Python\Python38\lib\site-packages\django\core\handlers\exception.py", line 34, in inner
    response = get_response(request)
  File "C:\Users\hp\AppData\Local\Programs\Python\Python38\lib\site-packages\django\core\handlers\base.py", line 115, in _get_response
    response = self.process_exception_by_middleware(e, request)
  File "C:\Users\hp\AppData\Local\Programs\Python\Python38\lib\site-packages\django\core\handlers\base.py", line 113, in _get_response
    response = wrapped_callback(request, *callback_args, **callback_kwargs)
  File "C:\Users\hp\AppData\Local\Programs\Python\Python38\lib\site-packages\django\views\generic\base.py", line 71, in view
    return self.dispatch(request, *args, **kwargs)
  File "C:\Users\hp\AppData\Local\Programs\Python\Python38\lib\site-packages\django\utils\decorators.py", line 43, in _wrapper
    return bound_method(*args, **kwargs)
  File "C:\Users\hp\AppData\Local\Programs\Python\Python38\lib\site-packages\django\views\decorators\cache.py", line 44, in _wrapped_view_func
    response = view_func(request, *args, **kwargs)
  File "C:\Users\hp\AppData\Local\Programs\Python\Python38\lib\site-packages\django\contrib\auth\views.py", line 118, in dispatch
    auth_logout(request)
  File "C:\Users\hp\AppData\Local\Programs\Python\Python38\lib\site-packages\django\contrib\auth\__init__.py", line 144, in logout
    user_logged_out.send(sender=user.__class__, request=request, user=user)
  File "C:\Users\hp\AppData\Local\Programs\Python\Python38\lib\site-packages\django\dispatch\dispatcher.py", line 173, in send
    return [
  File "C:\Users\hp\AppData\Local\Programs\Python\Python38\lib\site-packages\django\dispatch\dispatcher.py", line 174, in <listcomp>
    (receiver, receiver(signal=self, sender=sender, **named))
  File "C:\ecommerce\ecom\views.py", line 160, in log_user_logout
    print(ip)
NameError: name 'ip' is not defined
2021-09-11 21:09:57,365: C:\ecommerce\ecom\views.py changed, reloading.
2021-09-11 21:09:57,370: Using proactor: IocpProactor
2021-09-11 21:10:05,868: Internal Server Error: /logout
Traceback (most recent call last):
  File "C:\Users\hp\AppData\Local\Programs\Python\Python38\lib\site-packages\django\core\handlers\exception.py", line 34, in inner
    response = get_response(request)
  File "C:\Users\hp\AppData\Local\Programs\Python\Python38\lib\site-packages\django\core\handlers\base.py", line 115, in _get_response
    response = self.process_exception_by_middleware(e, request)
  File "C:\Users\hp\AppData\Local\Programs\Python\Python38\lib\site-packages\django\core\handlers\base.py", line 113, in _get_response
    response = wrapped_callback(request, *callback_args, **callback_kwargs)
  File "C:\Users\hp\AppData\Local\Programs\Python\Python38\lib\site-packages\django\views\generic\base.py", line 71, in view
    return self.dispatch(request, *args, **kwargs)
  File "C:\Users\hp\AppData\Local\Programs\Python\Python38\lib\site-packages\django\utils\decorators.py", line 43, in _wrapper
    return bound_method(*args, **kwargs)
  File "C:\Users\hp\AppData\Local\Programs\Python\Python38\lib\site-packages\django\views\decorators\cache.py", line 44, in _wrapped_view_func
    response = view_func(request, *args, **kwargs)
  File "C:\Users\hp\AppData\Local\Programs\Python\Python38\lib\site-packages\django\contrib\auth\views.py", line 118, in dispatch
    auth_logout(request)
  File "C:\Users\hp\AppData\Local\Programs\Python\Python38\lib\site-packages\django\contrib\auth\__init__.py", line 144, in logout
    user_logged_out.send(sender=user.__class__, request=request, user=user)
  File "C:\Users\hp\AppData\Local\Programs\Python\Python38\lib\site-packages\django\dispatch\dispatcher.py", line 173, in send
    return [
  File "C:\Users\hp\AppData\Local\Programs\Python\Python38\lib\site-packages\django\dispatch\dispatcher.py", line 174, in <listcomp>
    (receiver, receiver(signal=self, sender=sender, **named))
  File "C:\ecommerce\ecom\views.py", line 160, in log_user_logout
    print(ip)
NameError: name 'ip' is not defined
2021-09-11 21:12:45,334: C:\ecommerce\ecom\views.py changed, reloading.
2021-09-11 21:12:45,334: Using proactor: IocpProactor
2021-09-11 21:13:04,412: Internal Server Error: /logout
Traceback (most recent call last):
  File "C:\Users\hp\AppData\Local\Programs\Python\Python38\lib\site-packages\django\core\handlers\exception.py", line 34, in inner
    response = get_response(request)
  File "C:\Users\hp\AppData\Local\Programs\Python\Python38\lib\site-packages\django\core\handlers\base.py", line 115, in _get_response
    response = self.process_exception_by_middleware(e, request)
  File "C:\Users\hp\AppData\Local\Programs\Python\Python38\lib\site-packages\django\core\handlers\base.py", line 113, in _get_response
    response = wrapped_callback(request, *callback_args, **callback_kwargs)
  File "C:\Users\hp\AppData\Local\Programs\Python\Python38\lib\site-packages\django\views\generic\base.py", line 71, in view
    return self.dispatch(request, *args, **kwargs)
  File "C:\Users\hp\AppData\Local\Programs\Python\Python38\lib\site-packages\django\utils\decorators.py", line 43, in _wrapper
    return bound_method(*args, **kwargs)
  File "C:\Users\hp\AppData\Local\Programs\Python\Python38\lib\site-packages\django\views\decorators\cache.py", line 44, in _wrapped_view_func
    response = view_func(request, *args, **kwargs)
  File "C:\Users\hp\AppData\Local\Programs\Python\Python38\lib\site-packages\django\contrib\auth\views.py", line 118, in dispatch
    auth_logout(request)
  File "C:\Users\hp\AppData\Local\Programs\Python\Python38\lib\site-packages\django\contrib\auth\__init__.py", line 144, in logout
    user_logged_out.send(sender=user.__class__, request=request, user=user)
  File "C:\Users\hp\AppData\Local\Programs\Python\Python38\lib\site-packages\django\dispatch\dispatcher.py", line 173, in send
    return [
  File "C:\Users\hp\AppData\Local\Programs\Python\Python38\lib\site-packages\django\dispatch\dispatcher.py", line 174, in <listcomp>
    (receiver, receiver(signal=self, sender=sender, **named))
  File "C:\ecommerce\ecom\views.py", line 160, in log_user_logout
    print(ip)
NameError: name 'ip' is not defined
2021-09-11 21:13:25,673: C:\ecommerce\ecom\views.py changed, reloading.
2021-09-11 21:13:25,674: Using proactor: IocpProactor
2021-09-11 21:23:11,592: C:\ecommerce\ecom\views.py changed, reloading.
2021-09-11 21:23:11,594: Using proactor: IocpProactor
2021-09-11 21:23:45,517: C:\ecommerce\ecom\views.py changed, reloading.
2021-09-11 21:23:45,518: Using proactor: IocpProactor
2021-09-11 21:25:58,255: C:\ecommerce\ecom\views.py changed, reloading.
2021-09-11 21:25:58,256: Using proactor: IocpProactor
2021-09-11 21:26:12,308: Using proactor: IocpProactor
2021-09-11 21:28:34,044: C:\ecommerce\ecom\views.py changed, reloading.
2021-09-11 21:28:34,046: Using proactor: IocpProactor
2021-09-11 21:28:40,273: C:\ecommerce\ecom\views.py changed, reloading.
2021-09-11 21:28:40,275: Using proactor: IocpProactor
2021-09-11 21:29:20,208: C:\ecommerce\ecom\views.py changed, reloading.
2021-09-11 21:29:20,213: Using proactor: IocpProactor
2021-09-11 21:29:26,353: C:\ecommerce\datt.csv changed, reloading.
2021-09-11 21:29:26,353: Using proactor: IocpProactor
2021-09-11 21:30:35,007: C:\ecommerce\ecom\views.py changed, reloading.
2021-09-11 21:30:35,008: Using proactor: IocpProactor
2021-09-11 21:31:10,234: Using proactor: IocpProactor
2021-09-11 21:31:34,401: C:\ecommerce\ecom\views.py changed, reloading.
2021-09-11 21:31:34,401: Using proactor: IocpProactor
2021-09-11 21:31:38,686: C:\ecommerce\ecom\views.py changed, reloading.
2021-09-11 21:31:38,687: Using proactor: IocpProactor
2021-09-11 21:32:14,124: C:\ecommerce\ecom\views.py changed, reloading.
2021-09-11 21:32:14,125: Using proactor: IocpProactor
2021-09-11 21:32:26,409: C:\ecommerce\ecom\views.py changed, reloading.
2021-09-11 21:32:26,410: Using proactor: IocpProactor
2021-09-11 21:32:47,212: C:\ecommerce\ecom\views.py changed, reloading.
2021-09-11 21:32:47,213: Using proactor: IocpProactor
2021-09-11 21:33:33,312: C:\ecommerce\ecom\views.py changed, reloading.
2021-09-11 21:33:33,313: Using proactor: IocpProactor
2021-09-11 21:34:26,109: C:\ecommerce\ecom\views.py changed, reloading.
2021-09-11 21:34:26,110: Using proactor: IocpProactor
2021-09-11 21:35:11,529: C:\ecommerce\ecom\views.py changed, reloading.
2021-09-11 21:35:11,530: Using proactor: IocpProactor
2021-09-11 21:35:30,530: C:\ecommerce\ecom\views.py changed, reloading.
2021-09-11 21:35:30,531: Using proactor: IocpProactor
2021-09-11 21:36:53,093: C:\ecommerce\ecom\views.py changed, reloading.
2021-09-11 21:36:53,094: Using proactor: IocpProactor
2021-09-11 21:39:55,784: C:\ecommerce\ecom\views.py changed, reloading.
2021-09-11 21:39:55,785: Using proactor: IocpProactor
2021-09-11 21:41:36,028: C:\ecommerce\ecom\views.py changed, reloading.
2021-09-11 21:41:36,029: Using proactor: IocpProactor
2021-09-11 21:42:45,666: C:\ecommerce\ecom\views.py changed, reloading.
2021-09-11 21:42:45,667: Using proactor: IocpProactor
2021-09-11 21:44:14,861: C:\ecommerce\ecom\views.py changed, reloading.
2021-09-11 21:44:14,862: Using proactor: IocpProactor
2021-09-11 21:46:01,305: C:\ecommerce\ecom\views.py changed, reloading.
2021-09-11 21:46:01,306: Using proactor: IocpProactor
2021-09-11 21:46:37,112: C:\ecommerce\ecom\views.py changed, reloading.
2021-09-11 21:46:37,113: Using proactor: IocpProactor
2021-09-11 21:47:00,749: C:\ecommerce\ecom\views.py changed, reloading.
2021-09-11 21:47:00,751: Using proactor: IocpProactor
2021-09-11 21:47:31,651: C:\ecommerce\ecom\views.py changed, reloading.
2021-09-11 21:47:31,653: Using proactor: IocpProactor
2021-09-11 21:48:19,315: C:\ecommerce\ecom\views.py changed, reloading.
2021-09-11 21:48:19,316: Using proactor: IocpProactor
2021-09-11 21:49:41,563: C:\ecommerce\ecom\views.py changed, reloading.
2021-09-11 21:49:41,564: Using proactor: IocpProactor
2021-09-11 21:51:22,834: C:\ecommerce\ecom\views.py changed, reloading.
2021-09-11 21:51:22,835: Using proactor: IocpProactor
2021-09-11 21:52:33,222: C:\ecommerce\ecom\views.py changed, reloading.
2021-09-11 21:52:33,223: Using proactor: IocpProactor
2021-09-11 21:52:47,368: C:\ecommerce\ecom\views.py changed, reloading.
2021-09-11 21:52:47,369: Using proactor: IocpProactor
2021-09-11 21:55:28,480: C:\ecommerce\ecom\views.py changed, reloading.
2021-09-11 21:55:28,481: Using proactor: IocpProactor
2021-09-12 02:17:28,183: C:\ecommerce\ecom\views.py changed, reloading.
2021-09-12 02:17:28,197: Using proactor: IocpProactor
2021-09-12 02:21:08,369: Using proactor: IocpProactor
2021-09-12 02:22:17,401: C:\ecommerce\ecom\views.py changed, reloading.
2021-09-12 02:22:17,402: Using proactor: IocpProactor
2021-09-12 02:29:49,333: C:\ecommerce\ecom\views.py changed, reloading.
2021-09-12 02:29:49,334: Using proactor: IocpProactor
2021-09-12 02:30:57,945: C:\ecommerce\ecom\views.py changed, reloading.
2021-09-12 02:30:57,946: Using proactor: IocpProactor
2021-09-12 02:32:00,295: C:\ecommerce\ecom\views.py changed, reloading.
2021-09-12 02:32:00,297: Using proactor: IocpProactor
2021-09-12 02:58:08,887: C:\ecommerce\ecom\views.py changed, reloading.
2021-09-12 02:58:08,888: Using proactor: IocpProactor
2021-09-12 02:58:38,454: C:\ecommerce\ecom\views.py changed, reloading.
2021-09-12 02:58:38,455: Using proactor: IocpProactor
2021-09-12 03:00:35,724: C:\ecommerce\ecom\views.py changed, reloading.
2021-09-12 03:00:35,725: Using proactor: IocpProactor
2021-09-12 03:01:38,113: Using proactor: IocpProactor
2021-09-12 03:02:25,211: Using proactor: IocpProactor
2021-09-12 03:05:30,080: C:\ecommerce\ecom\views.py changed, reloading.
2021-09-12 03:05:30,081: Using proactor: IocpProactor
2021-09-12 03:06:40,094: C:\ecommerce\ecom\views.py changed, reloading.
2021-09-12 03:06:40,095: Using proactor: IocpProactor
2021-09-12 03:07:46,593: C:\ecommerce\ecom\views.py changed, reloading.
2021-09-12 03:07:46,595: Using proactor: IocpProactor
2021-09-12 03:07:59,042: Internal Server Error: /logout
Traceback (most recent call last):
  File "C:\Users\hp\AppData\Local\Programs\Python\Python38\lib\site-packages\django\core\handlers\exception.py", line 34, in inner
    response = get_response(request)
  File "C:\Users\hp\AppData\Local\Programs\Python\Python38\lib\site-packages\django\core\handlers\base.py", line 115, in _get_response
    response = self.process_exception_by_middleware(e, request)
  File "C:\Users\hp\AppData\Local\Programs\Python\Python38\lib\site-packages\django\core\handlers\base.py", line 113, in _get_response
    response = wrapped_callback(request, *callback_args, **callback_kwargs)
  File "C:\Users\hp\AppData\Local\Programs\Python\Python38\lib\site-packages\django\views\generic\base.py", line 71, in view
    return self.dispatch(request, *args, **kwargs)
  File "C:\Users\hp\AppData\Local\Programs\Python\Python38\lib\site-packages\django\utils\decorators.py", line 43, in _wrapper
    return bound_method(*args, **kwargs)
  File "C:\Users\hp\AppData\Local\Programs\Python\Python38\lib\site-packages\django\views\decorators\cache.py", line 44, in _wrapped_view_func
    response = view_func(request, *args, **kwargs)
  File "C:\Users\hp\AppData\Local\Programs\Python\Python38\lib\site-packages\django\contrib\auth\views.py", line 118, in dispatch
    auth_logout(request)
  File "C:\Users\hp\AppData\Local\Programs\Python\Python38\lib\site-packages\django\contrib\auth\__init__.py", line 144, in logout
    user_logged_out.send(sender=user.__class__, request=request, user=user)
  File "C:\Users\hp\AppData\Local\Programs\Python\Python38\lib\site-packages\django\dispatch\dispatcher.py", line 173, in send
    return [
  File "C:\Users\hp\AppData\Local\Programs\Python\Python38\lib\site-packages\django\dispatch\dispatcher.py", line 174, in <listcomp>
    (receiver, receiver(signal=self, sender=sender, **named))
  File "C:\ecommerce\ecom\views.py", line 180, in log_user_logout
    writer.writerow(data, activity)
TypeError: writerow() takes exactly one argument (2 given)
2021-09-12 03:08:22,009: C:\ecommerce\ecom\views.py changed, reloading.
2021-09-12 03:08:22,009: Using proactor: IocpProactor
2021-09-12 03:08:24,964: Internal Server Error: /logout
Traceback (most recent call last):
  File "C:\Users\hp\AppData\Local\Programs\Python\Python38\lib\site-packages\django\core\handlers\exception.py", line 34, in inner
    response = get_response(request)
  File "C:\Users\hp\AppData\Local\Programs\Python\Python38\lib\site-packages\django\core\handlers\base.py", line 115, in _get_response
    response = self.process_exception_by_middleware(e, request)
  File "C:\Users\hp\AppData\Local\Programs\Python\Python38\lib\site-packages\django\core\handlers\base.py", line 113, in _get_response
    response = wrapped_callback(request, *callback_args, **callback_kwargs)
  File "C:\Users\hp\AppData\Local\Programs\Python\Python38\lib\site-packages\django\views\generic\base.py", line 71, in view
    return self.dispatch(request, *args, **kwargs)
  File "C:\Users\hp\AppData\Local\Programs\Python\Python38\lib\site-packages\django\utils\decorators.py", line 43, in _wrapper
    return bound_method(*args, **kwargs)
  File "C:\Users\hp\AppData\Local\Programs\Python\Python38\lib\site-packages\django\views\decorators\cache.py", line 44, in _wrapped_view_func
    response = view_func(request, *args, **kwargs)
  File "C:\Users\hp\AppData\Local\Programs\Python\Python38\lib\site-packages\django\contrib\auth\views.py", line 118, in dispatch
    auth_logout(request)
  File "C:\Users\hp\AppData\Local\Programs\Python\Python38\lib\site-packages\django\contrib\auth\__init__.py", line 144, in logout
    user_logged_out.send(sender=user.__class__, request=request, user=user)
  File "C:\Users\hp\AppData\Local\Programs\Python\Python38\lib\site-packages\django\dispatch\dispatcher.py", line 173, in send
    return [
  File "C:\Users\hp\AppData\Local\Programs\Python\Python38\lib\site-packages\django\dispatch\dispatcher.py", line 174, in <listcomp>
    (receiver, receiver(signal=self, sender=sender, **named))
  File "C:\ecommerce\ecom\views.py", line 180, in log_user_logout
    writer.writerow(data, activity)
TypeError: writerow() takes exactly one argument (2 given)
2021-09-12 03:08:40,557: Internal Server Error: /my-profile
Traceback (most recent call last):
  File "C:\Users\hp\AppData\Local\Programs\Python\Python38\lib\site-packages\django\template\base.py", line 828, in _resolve_lookup
    current = current[bit]
TypeError: 'ImageFieldFile' object is not subscriptable

During handling of the above exception, another exception occurred:

Traceback (most recent call last):
  File "C:\Users\hp\AppData\Local\Programs\Python\Python38\lib\site-packages\django\core\handlers\exception.py", line 34, in inner
    response = get_response(request)
  File "C:\Users\hp\AppData\Local\Programs\Python\Python38\lib\site-packages\django\core\handlers\base.py", line 115, in _get_response
    response = self.process_exception_by_middleware(e, request)
  File "C:\Users\hp\AppData\Local\Programs\Python\Python38\lib\site-packages\django\core\handlers\base.py", line 113, in _get_response
    response = wrapped_callback(request, *callback_args, **callback_kwargs)
  File "C:\Users\hp\AppData\Local\Programs\Python\Python38\lib\site-packages\django\contrib\auth\decorators.py", line 21, in _wrapped_view
    return view_func(request, *args, **kwargs)
  File "C:\Users\hp\AppData\Local\Programs\Python\Python38\lib\site-packages\django\contrib\auth\decorators.py", line 21, in _wrapped_view
    return view_func(request, *args, **kwargs)
  File "C:\ecommerce\ecom\views.py", line 725, in my_profile_view
    return render(request,'ecom/my_profile.html',{'customer':customer})
  File "C:\Users\hp\AppData\Local\Programs\Python\Python38\lib\site-packages\django\shortcuts.py", line 19, in render
    content = loader.render_to_string(template_name, context, request, using=using)
  File "C:\Users\hp\AppData\Local\Programs\Python\Python38\lib\site-packages\django\template\loader.py", line 62, in render_to_string
    return template.render(context, request)
  File "C:\Users\hp\AppData\Local\Programs\Python\Python38\lib\site-packages\django\template\backends\django.py", line 61, in render
    return self.template.render(context)
  File "C:\Users\hp\AppData\Local\Programs\Python\Python38\lib\site-packages\django\template\base.py", line 171, in render
    return self._render(context)
  File "C:\Users\hp\AppData\Local\Programs\Python\Python38\lib\site-packages\django\template\base.py", line 163, in _render
    return self.nodelist.render(context)
  File "C:\Users\hp\AppData\Local\Programs\Python\Python38\lib\site-packages\django\template\base.py", line 936, in render
    bit = node.render_annotated(context)
  File "C:\Users\hp\AppData\Local\Programs\Python\Python38\lib\site-packages\django\template\base.py", line 903, in render_annotated
    return self.render(context)
  File "C:\Users\hp\AppData\Local\Programs\Python\Python38\lib\site-packages\django\template\loader_tags.py", line 150, in render
    return compiled_parent._render(context)
  File "C:\Users\hp\AppData\Local\Programs\Python\Python38\lib\site-packages\django\template\base.py", line 163, in _render
    return self.nodelist.render(context)
  File "C:\Users\hp\AppData\Local\Programs\Python\Python38\lib\site-packages\django\template\base.py", line 936, in render
    bit = node.render_annotated(context)
  File "C:\Users\hp\AppData\Local\Programs\Python\Python38\lib\site-packages\django\template\base.py", line 903, in render_annotated
    return self.render(context)
  File "C:\Users\hp\AppData\Local\Programs\Python\Python38\lib\site-packages\django\template\loader_tags.py", line 62, in render
    result = block.nodelist.render(context)
  File "C:\Users\hp\AppData\Local\Programs\Python\Python38\lib\site-packages\django\template\base.py", line 936, in render
    bit = node.render_annotated(context)
  File "C:\Users\hp\AppData\Local\Programs\Python\Python38\lib\site-packages\django\template\base.py", line 903, in render_annotated
    return self.render(context)
  File "C:\Users\hp\AppData\Local\Programs\Python\Python38\lib\site-packages\django\templatetags\static.py", line 106, in render
    url = self.url(context)
  File "C:\Users\hp\AppData\Local\Programs\Python\Python38\lib\site-packages\django\templatetags\static.py", line 102, in url
    path = self.path.resolve(context)
  File "C:\Users\hp\AppData\Local\Programs\Python\Python38\lib\site-packages\django\template\base.py", line 670, in resolve
    obj = self.var.resolve(context)
  File "C:\Users\hp\AppData\Local\Programs\Python\Python38\lib\site-packages\django\template\base.py", line 795, in resolve
    value = self._resolve_lookup(context)
  File "C:\Users\hp\AppData\Local\Programs\Python\Python38\lib\site-packages\django\template\base.py", line 836, in _resolve_lookup
    current = getattr(current, bit)
  File "C:\Users\hp\AppData\Local\Programs\Python\Python38\lib\site-packages\django\db\models\fields\files.py", line 61, in url
    self._require_file()
  File "C:\Users\hp\AppData\Local\Programs\Python\Python38\lib\site-packages\django\db\models\fields\files.py", line 38, in _require_file
    raise ValueError("The '%s' attribute has no file associated with it." % self.field.name)
ValueError: The 'profile_pic' attribute has no file associated with it.
2021-09-12 03:08:45,268: Internal Server Error: /logout
Traceback (most recent call last):
  File "C:\Users\hp\AppData\Local\Programs\Python\Python38\lib\site-packages\django\core\handlers\exception.py", line 34, in inner
    response = get_response(request)
  File "C:\Users\hp\AppData\Local\Programs\Python\Python38\lib\site-packages\django\core\handlers\base.py", line 115, in _get_response
    response = self.process_exception_by_middleware(e, request)
  File "C:\Users\hp\AppData\Local\Programs\Python\Python38\lib\site-packages\django\core\handlers\base.py", line 113, in _get_response
    response = wrapped_callback(request, *callback_args, **callback_kwargs)
  File "C:\Users\hp\AppData\Local\Programs\Python\Python38\lib\site-packages\django\views\generic\base.py", line 71, in view
    return self.dispatch(request, *args, **kwargs)
  File "C:\Users\hp\AppData\Local\Programs\Python\Python38\lib\site-packages\django\utils\decorators.py", line 43, in _wrapper
    return bound_method(*args, **kwargs)
  File "C:\Users\hp\AppData\Local\Programs\Python\Python38\lib\site-packages\django\views\decorators\cache.py", line 44, in _wrapped_view_func
    response = view_func(request, *args, **kwargs)
  File "C:\Users\hp\AppData\Local\Programs\Python\Python38\lib\site-packages\django\contrib\auth\views.py", line 118, in dispatch
    auth_logout(request)
  File "C:\Users\hp\AppData\Local\Programs\Python\Python38\lib\site-packages\django\contrib\auth\__init__.py", line 144, in logout
    user_logged_out.send(sender=user.__class__, request=request, user=user)
  File "C:\Users\hp\AppData\Local\Programs\Python\Python38\lib\site-packages\django\dispatch\dispatcher.py", line 173, in send
    return [
  File "C:\Users\hp\AppData\Local\Programs\Python\Python38\lib\site-packages\django\dispatch\dispatcher.py", line 174, in <listcomp>
    (receiver, receiver(signal=self, sender=sender, **named))
  File "C:\ecommerce\ecom\views.py", line 180, in log_user_logout
    writer.writerow(data, activity)
TypeError: writerow() takes exactly one argument (2 given)
2021-09-12 03:09:04,716: Using proactor: IocpProactor
2021-09-12 03:09:13,031: Internal Server Error: /logout
Traceback (most recent call last):
  File "C:\Users\hp\AppData\Local\Programs\Python\Python38\lib\site-packages\django\core\handlers\exception.py", line 34, in inner
    response = get_response(request)
  File "C:\Users\hp\AppData\Local\Programs\Python\Python38\lib\site-packages\django\core\handlers\base.py", line 115, in _get_response
    response = self.process_exception_by_middleware(e, request)
  File "C:\Users\hp\AppData\Local\Programs\Python\Python38\lib\site-packages\django\core\handlers\base.py", line 113, in _get_response
    response = wrapped_callback(request, *callback_args, **callback_kwargs)
  File "C:\Users\hp\AppData\Local\Programs\Python\Python38\lib\site-packages\django\views\generic\base.py", line 71, in view
    return self.dispatch(request, *args, **kwargs)
  File "C:\Users\hp\AppData\Local\Programs\Python\Python38\lib\site-packages\django\utils\decorators.py", line 43, in _wrapper
    return bound_method(*args, **kwargs)
  File "C:\Users\hp\AppData\Local\Programs\Python\Python38\lib\site-packages\django\views\decorators\cache.py", line 44, in _wrapped_view_func
    response = view_func(request, *args, **kwargs)
  File "C:\Users\hp\AppData\Local\Programs\Python\Python38\lib\site-packages\django\contrib\auth\views.py", line 118, in dispatch
    auth_logout(request)
  File "C:\Users\hp\AppData\Local\Programs\Python\Python38\lib\site-packages\django\contrib\auth\__init__.py", line 144, in logout
    user_logged_out.send(sender=user.__class__, request=request, user=user)
  File "C:\Users\hp\AppData\Local\Programs\Python\Python38\lib\site-packages\django\dispatch\dispatcher.py", line 173, in send
    return [
  File "C:\Users\hp\AppData\Local\Programs\Python\Python38\lib\site-packages\django\dispatch\dispatcher.py", line 174, in <listcomp>
    (receiver, receiver(signal=self, sender=sender, **named))
  File "C:\ecommerce\ecom\views.py", line 180, in log_user_logout
    writer.writerow(data, activity)
TypeError: writerow() takes exactly one argument (2 given)
2021-09-12 03:10:56,493: C:\ecommerce\ecom\views.py changed, reloading.
2021-09-12 03:10:56,494: Using proactor: IocpProactor
2021-09-12 03:14:20,219: C:\ecommerce\ecom\views.py changed, reloading.
2021-09-12 03:14:20,220: Using proactor: IocpProactor
2021-09-12 03:15:16,811: C:\ecommerce\ecom\views.py changed, reloading.
2021-09-12 03:15:16,812: Using proactor: IocpProactor
2021-09-12 03:15:31,883: C:\ecommerce\ecom\views.py changed, reloading.
2021-09-12 03:15:31,884: Using proactor: IocpProactor
2021-09-13 13:36:50,527: Using proactor: IocpProactor
2021-09-15 02:05:15,111: Using proactor: IocpProactor
2021-09-15 02:09:24,535: C:\ecommerce\ecom\views.py changed, reloading.
2021-09-15 02:09:24,537: Using proactor: IocpProactor
2021-09-15 02:13:15,787: C:\ecommerce\ecom\views.py changed, reloading.
2021-09-15 02:13:15,788: Using proactor: IocpProactor
2021-09-15 02:14:05,341: C:\ecommerce\ecom\views.py changed, reloading.
2021-09-15 02:14:05,342: Using proactor: IocpProactor
2021-09-15 02:15:13,729: C:\ecommerce\ecom\views.py changed, reloading.
2021-09-15 02:15:13,731: Using proactor: IocpProactor
2021-09-15 02:15:36,483: C:\ecommerce\ecom\views.py changed, reloading.
2021-09-15 02:15:36,486: Using proactor: IocpProactor
2021-09-15 02:17:15,948: C:\ecommerce\ecom\views.py changed, reloading.
2021-09-15 02:17:15,949: Using proactor: IocpProactor
2021-09-15 02:17:24,898: C:\ecommerce\ecom\views.py changed, reloading.
2021-09-15 02:17:24,900: Using proactor: IocpProactor
2021-09-15 02:17:35,749: C:\ecommerce\ecom\views.py changed, reloading.
2021-09-15 02:17:35,750: Using proactor: IocpProactor
2021-09-15 02:18:12,016: C:\ecommerce\ecom\views.py changed, reloading.
2021-09-15 02:18:12,017: Using proactor: IocpProactor
2021-09-15 02:20:05,037: C:\ecommerce\ecom\views.py changed, reloading.
2021-09-15 02:20:05,040: Using proactor: IocpProactor
2021-09-15 02:21:11,540: C:\ecommerce\ecom\views.py changed, reloading.
2021-09-15 02:21:11,541: Using proactor: IocpProactor
2021-09-16 14:55:01,259: Not Found: /favicon.ico
2021-09-26 15:09:00,554: Not Found: /favicon.ico
2021-09-30 03:52:12,523: Not Found: /favicon.ico
2021-09-30 03:53:47,137: Internal Server Error: /logout
Traceback (most recent call last):
  File "C:\Users\hp\AppData\Local\Programs\Python\Python38\lib\site-packages\django\core\handlers\exception.py", line 34, in inner
    response = get_response(request)
  File "C:\Users\hp\AppData\Local\Programs\Python\Python38\lib\site-packages\django\core\handlers\base.py", line 115, in _get_response
    response = self.process_exception_by_middleware(e, request)
  File "C:\Users\hp\AppData\Local\Programs\Python\Python38\lib\site-packages\django\core\handlers\base.py", line 113, in _get_response
    response = wrapped_callback(request, *callback_args, **callback_kwargs)
  File "C:\Users\hp\AppData\Local\Programs\Python\Python38\lib\site-packages\django\views\generic\base.py", line 71, in view
    return self.dispatch(request, *args, **kwargs)
  File "C:\Users\hp\AppData\Local\Programs\Python\Python38\lib\site-packages\django\utils\decorators.py", line 43, in _wrapper
    return bound_method(*args, **kwargs)
  File "C:\Users\hp\AppData\Local\Programs\Python\Python38\lib\site-packages\django\views\decorators\cache.py", line 44, in _wrapped_view_func
    response = view_func(request, *args, **kwargs)
  File "C:\Users\hp\AppData\Local\Programs\Python\Python38\lib\site-packages\django\contrib\auth\views.py", line 118, in dispatch
    auth_logout(request)
  File "C:\Users\hp\AppData\Local\Programs\Python\Python38\lib\site-packages\django\contrib\auth\__init__.py", line 144, in logout
    user_logged_out.send(sender=user.__class__, request=request, user=user)
  File "C:\Users\hp\AppData\Local\Programs\Python\Python38\lib\site-packages\django\dispatch\dispatcher.py", line 173, in send
    return [
  File "C:\Users\hp\AppData\Local\Programs\Python\Python38\lib\site-packages\django\dispatch\dispatcher.py", line 174, in <listcomp>
    (receiver, receiver(signal=self, sender=sender, **named))
  File "C:\ecommerce\ecom\views.py", line 177, in log_user_logout
    print('user {} logged out through page {} at time {}'.format(user.username, request.META.get('HTTP_REFERER'), current_time))
AttributeError: 'NoneType' object has no attribute 'username'
